Workbook
Name Slicer_Bonus_Percentage: #N/A
Name Slicer_Dept_Code: #N/A
Name Slicer_Employment_Status: #N/A
Name Slicer_Performance_Band: #N/A

Sheet Dashboard

Sheet Analysis Chart

Sheet Analysis
A2: Headcount and Salary | D2: Attrition Rate | K2: Average Years of Service
A3: Total headcount | D3: Count of Emp ID | E3: Column Labels | K3: Row Labels | L3: Average of Years of Service
A4: 150 | B4: =GETPIVOTDATA("Emp ID",$A$3) -> 150 | D4: Row Labels | E4: Active | F4: Left | G4: Resigned | H4: Grand Total | I4: Attrition Rate | K4: Finance | L4: 6.7769608
D5: Finance | E5: 14 | F5: 3 | H5: 17 | I5: =F5/H5 -> 0.17647059 | K5: Human Resources | L5: 7.5608025
D6: Human Resources | E6: 15 | F6: 2 | G6: 1 | H6: 18 | I6: =F6/H6 -> 0.11111111 | K6: Information Technology | L6: 7.1072531
A7: Row Labels | B7: Average Salary | D7: Information Technology | E7: 28 | F7: 6 | G7: 2 | H7: 36 | I7: =F7/H7 -> 0.16666667 | K7: Marketing | L7: 6.6296296
A8: Human Resources | B8: 85969.833 | D8: Marketing | E8: 15 | F8: 3 | H8: 18 | I8: =F8/H8 -> 0.16666667 | K8: Operations | L8: 6.7363799
A9: Information Technology | B9: 85159.25 | D9: Operations | E9: 21 | F9: 5 | G9: 5 | H9: 31 | I9: =F9/H9 -> 0.16129032 | K9: Sales | L9: 6.7587037
A10: Sales | B10: 84550.833 | D10: Sales | E10: 24 | F10: 4 | G10: 2 | H10: 30 | I10: =F10/H10 -> 0.13333333
A11: Operations | B11: 81846.71
A12: Marketing | B12: 81577.278 | D12: Overall Attrition Rate | E12: =GETPIVOTDATA("Emp ID",$A$32,"Employment Status","Left")/B4 -> 0.15333333 | F12: =E12 -> 0.15333333
A13: Finance | B13: 81484.529
H14: Employee Distribution by Department | K14: Performance Band by department
D15: Bonus Payout | H15: Row Labels | I15: Count of Emp ID | K15: Count of Emp ID | L15: Column Labels
A16: Performance by Status | D16: Row Labels | E16: Sum of Bonus Amount | H16: Information Technology | I16: 36 | K16: Row Labels | L16: Achieving | M16: Developing | N16: Exceeding | O16: Needs Improvement | P16: Outstanding
A17: Row Labels | B17: Average of Perf_Score | D17: Achieving | E17: 165216.95 | H17: Operations | I17: 31 | K17: Information Technology | L17: 9 | M17: 12 | N17: 8 | O17: 5 | P17: 2
A18: Active | B18: 68.34188 | D18: Exceeding | E18: 144689.44 | H18: Sales | I18: 30 | K18: Operations | L18: 10 | M18: 10 | N18: 2 | O18: 7 | P18: 2
A19: Left | B19: 70.26087 | D19: Outstanding | E19: 92411.52 | H19: Human Resources | I19: 18 | K19: Sales | L19: 10 | M19: 8 | N19: 6 | O19: 5 | P19: 1
A20: Resigned | B20: 59.9 | D20: Developing | E20: 84593.28 | H20: Marketing | I20: 18 | K20: Human Resources | L20: 4 | M20: 7 | N20: 2 | O20: 4 | P20: 1
D21: Needs Improvement | E21: 0 | H21: Finance | I21: 17 | K21: Marketing | L21: 4 | M21: 8 | N21: 1 | O21: 3 | P21: 2
K22: Finance | L22: 4 | M22: 4 | N22: 3 | O22: 4 | P22: 2
A23: Employee Distribution by Status | D23: Total Bonus Payout
A24: Row Labels | B24: Count of Emp ID | D24: 486911.19 | E24: =GETPIVOTDATA("Bonus Amount",$D$23) -> 486911.19 | H24: Average of Perf_Score
A25: Active | B25: 0.78 | H25: 68.073333 | I25: =GETPIVOTDATA("Perf_Score",$H$24) -> 68.073333
A26: Left | B26: 0.15333333 | D26: Employee Distribution By Performance Band
A27: Resigned | B27: 0.066666667 | D27: Row Labels | E27: Employee Count
D28: Achieving | E28: 41
D29: Developing | E29: 49
D30: Exceeding | E30: 22
A31: Employee Distribution by Status | D31: Needs Improvement | E31: 28
A32: Row Labels | B32: Count of Emp ID | D32: Outstanding | E32: 10
A33: Active | B33: 117 | C33: =GETPIVOTDATA("Emp ID",$A$32,"Employment Status","Active") -> 117
A34: Left | B34: 23
A35: Resigned | B35: 10

Sheet Cleaned_Employee_Data 
A1: Emp ID | B1: Names | C1: Dept Code | D1: Department_Name | E1: Hire Date | F1: Years of Service | G1: Salary | H1: Perf_Score | I1: Performance_Band | J1: Bonus_Percentage | K1: Employment Status | L1: Bonus Amount
A2: EMP127 | B2: =CONCATENATE(Raw_Employee_Data!B2," ",Raw_Employee_Data!C2) -> Emily Brown | C2: =UPPER(TRIM(Raw_Employee_Data!D1:D158)) -> IT02 | D2: =VLOOKUP(C2,Lookup_Departments!$A$1:$B$7,2,) -> Information Technology | E2: 43093 | F2: =YEARFRAC(E2,TODAY()) -> 8.5333333 | G2: 50361 | H2: 52 | I2: =VLOOKUP(H2,Lookup_Performance!$A$1:$D$6,3) -> Developing | J2: =VLOOKUP(H2,Lookup_Performance!$A$1:$D$6,4) -> 0.02 | K2: =PROPER(TRIM(Raw_Employee_Data!H1:H158)) -> Active | L2: =Table1[[#This Row],[Salary]]*Table1[[#This Row],[Bonus_Percentage]] -> 1007.22
A3: EMP046 | B3: =CONCATENATE(Raw_Employee_Data!B3," ",Raw_Employee_Data!C3) -> Richard Hernandez | C3: =UPPER(TRIM(Raw_Employee_Data!D2:D159)) -> MKT04 | D3: =VLOOKUP(C3,Lookup_Departments!$A$1:$B$7,2,) -> Marketing | E3: 44659 | F3: =YEARFRAC(E3,TODAY()) -> 4.2444444 | G3: 112673 | H3: 68 | I3: =VLOOKUP(H3,Lookup_Performance!$A$1:$D$6,3) -> Developing | J3: =VLOOKUP(H3,Lookup_Performance!$A$1:$D$6,4) -> 0.02 | K3: =PROPER(TRIM(Raw_Employee_Data!H2:H159)) -> Active | L3: =Table1[[#This Row],[Salary]]*Table1[[#This Row],[Bonus_Percentage]] -> 2253.46
A4: EMP134 | B4: =CONCATENATE(Raw_Employee_Data!B4," ",Raw_Employee_Data!C4) -> Emily Gonzalez | C4: =UPPER(TRIM(Raw_Employee_Data!D3:D160)) -> IT02 | D4: =VLOOKUP(C4,Lookup_Departments!$A$1:$B$7,2,) -> Information Technology | E4: 42431 | F4: =YEARFRAC(E4,TODAY()) -> 10.344444 | G4: 114425 | H4: 54 | I4: =VLOOKUP(H4,Lookup_Performance!$A$1:$D$6,3) -> Developing | J4: =VLOOKUP(H4,Lookup_Performance!$A$1:$D$6,4) -> 0.02 | K4: =PROPER(TRIM(Raw_Employee_Data!H3:H160)) -> Left | L4: =Table1[[#This Row],[Salary]]*Table1[[#This Row],[Bonus_Percentage]] -> 2288.5
A5: EMP139 | B5: =CONCATENATE(Raw_Employee_Data!B5," ",Raw_Employee_Data!C5) -> John Martinez | C5: =UPPER(TRIM(Raw_Employee_Data!D4:D161)) -> FIN03 | D5: =VLOOKUP(C5,Lookup_Departments!$A$1:$B$7,2,) -> Finance | E5: 45110 | F5: =YEARFRAC(E5,TODAY()) -> 3.0083333 | G5: 103831 | H5: 70 | I5: =VLOOKUP(H5,Lookup_Performance!$A$1:$D$6,3) -> Achieving | J5: =VLOOKUP(H5,Lookup_Performance!$A$1:$D$6,4) -> 0.05 | K5: =PROPER(TRIM(Raw_Employee_Data!H4:H161)) -> Active | L5: =Table1[[#This Row],[Salary]]*Table1[[#This Row],[Bonus_Percentage]] -> 5191.55
A6: EMP112 | B6: =CONCATENATE(Raw_Employee_Data!B6," ",Raw_Employee_Data!C6) -> Thomas Smith | C6: =UPPER(TRIM(Raw_Employee_Data!D5:D162)) -> IT02 | D6: =VLOOKUP(C6,Lookup_Departments!$A$1:$B$7,2,) -> Information Technology | E6: 44977 | F6: =YEARFRAC(E6,TODAY()) -> 3.3777778 | G6: 73785 | H6: 40 | I6: =VLOOKUP(H6,Lookup_Performance!$A$1:$D$6,3) -> Needs Improvement | J6: =VLOOKUP(H6,Lookup_Performance!$A$1:$D$6,4) -> 0 | K6: =PROPER(TRIM(Raw_Employee_Data!H5:H162)) -> Left | L6: =Table1[[#This Row],[Salary]]*Table1[[#This Row],[Bonus_Percentage]] -> 0
A7: EMP030 | B7: =CONCATENATE(Raw_Employee_Data!B7," ",Raw_Employee_Data!C7) -> Emily Johnson | C7: =UPPER(TRIM(Raw_Employee_Data!D6:D163)) -> OPS06 | D7: =VLOOKUP(C7,Lookup_Departments!$A$1:$B$7,2,) -> Operations | E7: 43892 | F7: =YEARFRAC(E7,TODAY()) -> 6.3444444 | G7: 115882 | H7: 49 | I7: =VLOOKUP(H7,Lookup_Performance!$A$1:$D$6,3) -> Needs Improvement | J7: =VLOOKUP(H7,Lookup_Performance!$A$1:$D$6,4) -> 0 | K7: =PROPER(TRIM(Raw_Employee_Data!H6:H163)) -> Active | L7: =Table1[[#This Row],[Salary]]*Table1[[#This Row],[Bonus_Percentage]] -> 0
A8: EMP096 | B8: =CONCATENATE(Raw_Employee_Data!B8," ",Raw_Employee_Data!C8) -> John Wilson | C8: =UPPER(TRIM(Raw_Employee_Data!D7:D164)) -> OPS06 | D8: =VLOOKUP(C8,Lookup_Departments!$A$1:$B$7,2,) -> Operations | E8: 45272 | F8: =YEARFRAC(E8,TODAY()) -> 2.5666667 | G8: 59980 | H8: 70 | I8: =VLOOKUP(H8,Lookup_Performance!$A$1:$D$6,3) -> Achieving | J8: =VLOOKUP(H8,Lookup_Performance!$A$1:$D$6,4) -> 0.05 | K8: =PROPER(TRIM(Raw_Employee_Data!H7:H164)) -> Left | L8: =Table1[[#This Row],[Salary]]*Table1[[#This Row],[Bonus_Percentage]] -> 2999
A9: EMP098 | B9: =CONCATENATE(Raw_Employee_Data!B9," ",Raw_Employee_Data!C9) -> Jessica Smith | C9: =UPPER(TRIM(Raw_Employee_Data!D8:D165)) -> OPS06 | D9: =VLOOKUP(C9,Lookup_Departments!$A$1:$B$7,2,) -> Operations | E9: 44174 | F9: =YEARFRAC(E9,TODAY()) -> 5.575 | G9: 68728 | H9: 45 | I9: =VLOOKUP(H9,Lookup_Performance!$A$1:$D$6,3) -> Needs Improvement | J9: =VLOOKUP(H9,Lookup_Performance!$A$1:$D$6,4) -> 0 | K9: =PROPER(TRIM(Raw_Employee_Data!H8:H165)) -> Active | L9: =Table1[[#This Row],[Salary]]*Table1[[#This Row],[Bonus_Percentage]] -> 0
A10: EMP095 | B10: =CONCATENATE(Raw_Employee_Data!B10," ",Raw_Employee_Data!C10) -> Rodriguez | C10: =UPPER(TRIM(Raw_Employee_Data!D9:D166)) -> FIN03 | D10: =VLOOKUP(C10,Lookup_Departments!$A$1:$B$7,2,) -> Finance | E10: 43107 | F10: =YEARFRAC(E10,TODAY()) -> 8.4972222 | G10: 102139 | H10: 79 | I10: =VLOOKUP(H10,Lookup_Performance!$A$1:$D$6,3) -> Achieving | J10: =VLOOKUP(H10,Lookup_Performance!$A$1:$D$6,4) -> 0.05 | K10: =PROPER(TRIM(Raw_Employee_Data!H9:H166)) -> Active | L10: =Table1[[#This Row],[Salary]]*Table1[[#This Row],[Bonus_Percentage]] -> 5106.95
A11: EMP140 | B11: =CONCATENATE(Raw_Employee_Data!B11," ",Raw_Employee_Data!C11) -> Michael Martinez | C11: =UPPER(TRIM(Raw_Employee_Data!D10:D167)) -> SAL05 | D11: =VLOOKUP(C11,Lookup_Departments!$A$1:$B$7,2,) -> Sales | E11: 42676 | F11: =YEARFRAC(E11,TODAY()) -> 9.6777778 | G11: 94998 | H11: 58 | I11: =VLOOKUP(H11,Lookup_Performance!$A$1:$D$6,3) -> Developing | J11: =VLOOKUP(H11,Lookup_Performance!$A$1:$D$6,4) -> 0.02 | K11: =PROPER(TRIM(Raw_Employee_Data!H10:H167)) -> Active | L11: =Table1[[#This Row],[Salary]]*Table1[[#This Row],[Bonus_Percentage]] -> 1899.96
A12: EMP020 | B12: =CONCATENATE(Raw_Employee_Data!B12," ",Raw_Employee_Data!C12) -> Emily Miller | C12: =UPPER(TRIM(Raw_Employee_Data!D11:D168)) -> SAL05 | D12: =VLOOKUP(C12,Lookup_Departments!$A$1:$B$7,2,) -> Sales | E12: 43911 | F12: =YEARFRAC(E12,TODAY()) -> 6.2916667 | G12: 118635 | H12: 49 | I12: =VLOOKUP(H12,Lookup_Performance!$A$1:$D$6,3) -> Needs Improvement | J12: =VLOOKUP(H12,Lookup_Performance!$A$1:$D$6,4) -> 0 | K12: =PROPER(TRIM(Raw_Employee_Data!H11:H168)) -> Active | L12: =Table1[[#This Row],[Salary]]*Table1[[#This Row],[Bonus_Percentage]] -> 0
A13: EMP057 | B13: =CONCATENATE(Raw_Employee_Data!B13," ",Raw_Employee_Data!C13) -> Emily Hernandez | C13: =UPPER(TRIM(Raw_Employee_Data!D12:D169)) -> IT02 | D13: =VLOOKUP(C13,Lookup_Departments!$A$1:$B$7,2,) -> Information Technology | E13: 42425 | F13: =YEARFRAC(E13,TODAY()) -> 10.363889 | G13: 76918 | H13: 62 | I13: =VLOOKUP(H13,Lookup_Performance!$A$1:$D$6,3) -> Developing | J13: =VLOOKUP(H13,Lookup_Performance!$A$1:$D$6,4) -> 0.02 | K13: =PROPER(TRIM(Raw_Employee_Data!H12:H169)) -> Active | L13: =Table1[[#This Row],[Salary]]*Table1[[#This Row],[Bonus_Percentage]] -> 1538.36
... A151: EMP103 | B151: =CONCATENATE(Raw_Employee_Data!B151," ",Raw_Employee_Data!C151) -> Jones | C151: =UPPER(TRIM(Raw_Employee_Data!D150:D307)) -> IT02 | D151: =VLOOKUP(C151,Lookup_Departments!$A$1:$B$7,2,) -> Information Technology | E151: 44848 | F151: =YEARFRAC(E151,TODAY()) -> 3.7277778 | G151: 118634 | H151: 91 | I151: =VLOOKUP(H151,Lookup_Performance!$A$1:$D$6,3) -> Exceeding | J151: =VLOOKUP(H151,Lookup_Performance!$A$1:$D$6,4) -> 0.08 | K151: =PROPER(TRIM(Raw_Employee_Data!H150:H307)) -> Active | L151: =Table1[[#This Row],[Salary]]*Table1[[#This Row],[Bonus_Percentage]] -> 9490.72
G152: =AVERAGE(G1:G151) -> 83603.94 | H152: =AVERAGE(H1:H151) -> 68.073333

Sheet Raw_Employee_Data
A1: Emp ID | B1: First_Name | C1: Last_Name | D1: Dept Code | E1: Hire Date | F1: Salary | G1: Perf_Score | H1: Employment Status
A2: EMP127 | B2: Emily | C2: Brown | D2: IT02 | E2: 43093 | F2: 50361 | G2: 52 | H2: active
A3: EMP046 | B3: Richard | C3: Hernandez | D3: MKT04 | E3: 44659 | F3: 112673 | H3: ACTIVE
A4: EMP134 | B4: Emily | C4: Gonzalez | D4: IT02 | E4: 42431 | F4: $114,425 | G4: 54 | H4: LEFT
A5: EMP139 | B5: John | C5: Martinez | D5: FIN03 | E5: 45110 | F5: 103831 | G5: 70 | H5: active
A6: EMP112 | B6: Thomas | C6: Smith | D6: IT02 | E6: 44977 | F6: 73785 | G6: 40 | H6: Left
A7: EMP030 | B7: Emily | C7: Johnson | D7: OPS06 | E7: 02-Mar-20 | F7: 115882 | G7: 49 | H7: ACTIVE
A8: EMP096 | B8: John | C8: Wilson | D8: OPS06 | E8: 45272 | F8: 59980 | G8: 70 | H8: Left
A9: EMP098 | B9: Jessica | C9: Smith | D9: OPS06 | E9: 44174 | F9: 68728 | G9: 45 | H9: ACTIVE
A10: EMP095 | C10: Rodriguez | D10: FIN03 | E10: 43107 | F10: 102139 | G10: 79 | H10: active
A11: EMP140 | B11: Michael | C11: Martinez | D11: SAL05 | E11: 42676 | F11: 94998 | G11: 58 | H11: Active
A12: EMP020 | B12: Emily | C12: Miller | D12: sal05 | E12: 43911 | F12: $118,635 | G12: 49 | H12: Active
A13: EMP057 | B13: Emily | C13: Hernandez | D13: IT02 | E13: 42425 | F13: 76918 | G13: 62 | H13: Active
A14: EMP016 | B14: Jane | C14: Williams | D14: mkt04 | E14: 17-Jun-21 | F14: 61408 | G14: 48 | H14: ACTIVE
A15: EMP070 | B15: Jane | C15: Miller | D15: MKT04 | E15: 44001 | F15: 99990 | G15: 54 | H15: Active
A16: EMP025 | B16: Robert | C16: Jones | D16: MKT04 | E16: 43820 | F16: 80385 | H16: active
A17: EMP031 | B17: Thomas | C17: Rodriguez | D17: SAL05 | E17: 45169 | F17: 65290 | G17: 77 | H17: active
A18: EMP126 | B18: Emily | C18: Davis | D18: IT02 | E18: 42337 | F18: 105765 | G18: 42 | H18: Active
A19: EMP109 | B19: James | C19: Martinez | D19: SAL05 | E19: 42899 | F19: 102921 | G19: 49 | H19: ACTIVE
A20: EMP057 | B20: Emily | C20: Hernandez | D20: IT02 | E20: 42425 | F20: 76918 | G20: 62 | H20: Active
A21: EMP066 | B21: Ashley | C21: Lopez | D21: MKT04 | E21: 43235 | F21: 73984 | G21: 93 | H21: Active
A22: EMP120 | B22: Amanda | C22: Gonzalez | D22: IT02 | E22: 42575 | G22: 75 | H22: Active
A23: EMP019 | B23: Michael | C23: Hernandez | D23: FIN03 | E23: 43076 | F23: 118527 | G23: 50 | H23: Active
A24: EMP013 | B24: Richard | C24: Hernandez | D24: MKT04 | E24: 44353 | F24: 107871 | G24: 88 | H24: active
A25: EMP010 | B25: Michael | C25: Rodriguez | D25: IT02 | E25: 44815 | F25: 93956 | G25: 50 | H25: LEFT
A26: EMP032 | B26: Jessica | C26: Johnson | D26: FIN03 | E26: 42565 | F26: 100851 | G26: 64 | H26: ACTIVE
A27: EMP082 | B27: Ashley | C27: Williams | D27: SAL05 | E27: 44728 | F27: 68655 | G27: 32 | H27: active
A28: EMP052 | C28: Williams | D28: SAL05 | E28: 45134 | F28: 81205 | G28: 59 | H28: Active
A29: EMP129 | B29: John | C29: Wilson | D29: SAL05 | E29: 09/24/2019 | F29: $77,610 | G29: 88 | H29: Active
A30: EMP146 | B30: Thomas | C30: Rodriguez | D30: it02 | E30: 44765 | F30: $50,873 | G30: 90 | H30: Active
A31: EMP099 | B31: Michael | C31: Wilson | D31: fin03 | E31: 13-May-18 | F31: 85312 | G31: 66 | H31: active
A32: EMP015 | B32: John | C32: Rodriguez | D32: SAL05 | E32: 42202 | G32: 68 | H32: active
A33: EMP076 | B33: Thomas | C33: Hernandez | D33: OPS06 | E33: 05-Aug-15 | F33: 97055 | G33: 80 | H33: Active
A34: EMP137 | B34: Michael | C34: Johnson | D34: IT02 | E34: 45195 | F34: 66069 | G34: 72 | H34: Active
A35: EMP056 | B35: Sarah | C35: Brown | D35: it02 | E35: 10-Jun-19 | F35: 90157 | G35: 58 | H35: active
A36: EMP125 | B36: Jane | C36: Martinez | D36: HR01 | E36: 44578 | F36: 59899 | G36: 78 | H36: Active
A37: EMP085 | B37: Emily | C37: Jones | D37: FIN03 | E37: 03-Jul-17 | F37: 113389 | G37: 30 | H37: ACTIVE
A38: EMP106 | C38: Brown | D38: IT02 | E38: 01-Sep-15 | F38: 102691 | G38: 52 | H38: Active
A39: EMP043 | B39: John | C39: Wilson | D39: OPS06 | E39: 03-Aug-22 | F39: 111845 | G39: 98 | H39: active
A40: EMP068 | B40: Melissa | C40: Brown | D40: SAL05 | E40: 06/29/2022 | F40: 69219 | G40: 93 | H40: Active
...

Sheet Lookup_Departments
A1: Dept_Code | B1: Department_Name
A2: HR01 | B2: Human Resources
A3: IT02 | B3: Information Technology
A4: FIN03 | B4: Finance
A5: MKT04 | B5: Marketing
A6: SAL05 | B6: Sales
A7: OPS06 | B7: Operations

Sheet Lookup_Performance
A1: Min_Score | B1: Max_Score | C1: Performance_Band | D1: Bonus_Percentage
A2: 0 | B2: 49 | C2: Needs Improvement | D2: 0
A3: 50 | B3: 69 | C3: Developing | D3: 0.02
A4: 70 | B4: 84 | C4: Achieving | D4: 0.05
A5: 85 | B5: 94 | C5: Exceeding | D5: 0.08
A6: 95 | B6: 100 | C6: Outstanding | D6: 0.12
